reported_result/report-0/ART/output/output0.txt

Iceberg	1	4	4	4	1	BUY 	0	---	0
NewOrderRs	Rejected
	Trades	0
	Orders	0
	Credits	7
	Credit	1	15
	Credit	2	20
	Credit	3	16
	Credit	4	9
	Credit	5	5
	Credit	6	10
	Credit	7	20
	Ownerships	7
	Ownership	1	17
	Ownership	2	7
	Ownership	3	72
	Ownership	4	57
	Ownership	5	41
	Ownership	6	42
	Ownership	7	42
	ReferencePrice	5
	StaticPriceBandLowerLimit	0.6
	StaticPriceBandUpperLimit	0.8
	TotalShares	100
	OwnershipUpperLimit	0.2
	TickSize	1
	LotSize	1
Iceberg	2	2	7	6	5	SELL	2	---	0
NewOrderRs	Eliminated
	Trades	0
	Orders	0
	Credits	7
	Credit	1	15
	Credit	2	20
	Credit	3	16
	Credit	4	9
	Credit	5	5
	Credit	6	10
	Credit	7	20
	Ownerships	7
	Ownership	1	17
	Ownership	2	7
	Ownership	3	72
	Ownership	4	57
	Ownership	5	41
	Ownership	6	42
	Ownership	7	42
	ReferencePrice	5
	StaticPriceBandLowerLimit	0.6
	StaticPriceBandUpperLimit	0.8
	TotalShares	100
	OwnershipUpperLimit	0.2
	TickSize	1
	LotSize	1
Limit	3	4	7	7	5	SELL	0	---	0
NewOrderRs	Accepted
	Trades	0
	Orders	1
	Order	Limit	3	4	7	7	5	SELL	0	---	0
	Credits	7
	Credit	1	15
	Credit	2	20
	Credit	3	16
	Credit	4	9
	Credit	5	5
	Credit	6	10
	Credit	7	20
	Ownerships	7
	Ownership	1	17
	Ownership	2	7
	Ownership	3	72
	Ownership	4	57
	Ownership	5	41
	Ownership	6	42
	Ownership	7	42
	ReferencePrice	5
	StaticPriceBandLowerLimit	0.6
	StaticPriceBandUpperLimit	0.8
	TotalShares	100
	OwnershipUpperLimit	0.2
	TickSize	1
	LotSize	1
Limit	4	5	7	1	4	BUY 	4	---	0
NewOrderRs	Rejected
	Trades	0
	Orders	1
	Order	Limit	3	4	7	7	5	SELL	0	---	0
	Credits	7
	Credit	1	15
	Credit	2	20
	Credit	3	16
	Credit	4	9
	Credit	5	5
	Credit	6	10
	Credit	7	20
	Ownerships	7
	Ownership	1	17
	Ownership	2	7
	Ownership	3	72
	Ownership	4	57
	Ownership	5	41
	Ownership	6	42
	Ownership	7	42
	ReferencePrice	5
	StaticPriceBandLowerLimit	0.6
	StaticPriceBandUpperLimit	0.8
	TotalShares	100
	OwnershipUpperLimit	0.2
	TickSize	1
	LotSize	1
CancelOrderRs	Rejected
	Orders	1
	Order	Limit	3	4	7	7	5	SELL	0	---	0
	Credits	7
	Credit	1	15
	Credit	2	20
	Credit	3	16
	Credit	4	9
	Credit	5	5
	Credit	6	10
	Credit	7	20
	Ownerships	7
	Ownership	1	17
	Ownership	2	7
	Ownership	3	72
	Ownership	4	57
	Ownership	5	41
	Ownership	6	42
	Ownership	7	42
	ReferencePrice	5
	StaticPriceBandLowerLimit	0.6
	StaticPriceBandUpperLimit	0.8
	TotalShares	100
	OwnershipUpperLimit	0.2
	TickSize	1
	LotSize	1
Limit	6	7	6	7	1	BUY 	1	---	0
NewOrderRs	Rejected
	Trades	0
	Orders	1
	Order	Limit	3	4	7	7	5	SELL	0	---	0
	Credits	7
	Credit	1	15
	Credit	2	20
	Credit	3	16
	Credit	4	9
	Credit	5	5
	Credit	6	10
	Credit	7	20
	Ownerships	7
	Ownership	1	17
	Ownership	2	7
	Ownership	3	72
	Ownership	4	57
	Ownership	5	41
	Ownership	6	42
	Ownership	7	42
	ReferencePrice	5
	StaticPriceBandLowerLimit	0.6
	StaticPriceBandUpperLimit	0.8
	TotalShares	100
	OwnershipUpperLimit	0.2
	TickSize	1
	LotSize	1
Iceberg	7	2	6	4	5	SELL	0	---	0
NewOrderRs	Accepted
	Trades	0
	Orders	2
	Order	Iceberg	7	2	6	4	5	SELL	0	---	3
	Order	Limit	3	4	7	7	5	SELL	0	---	0
	Credits	7
	Credit	1	15
	Credit	2	20
	Credit	3	16
	Credit	4	9
	Credit	5	5
	Credit	6	10
	Credit	7	20
	Ownerships	7
	Ownership	1	17
	Ownership	2	7
	Ownership	3	72
	Ownership	4	57
	Ownership	5	41
	Ownership	6	42
	Ownership	7	42
	ReferencePrice	5
	StaticPriceBandLowerLimit	0.6
	StaticPriceBandUpperLimit	0.8
	TotalShares	100
	OwnershipUpperLimit	0.2
	TickSize	1
	LotSize	1
Limit	8	6	6	2	3	SELL	0	FAK	0
NewOrderRs	Eliminated
	Trades	0
	Orders	2
	Order	Iceberg	7	2	6	4	5	SELL	0	---	3
	Order	Limit	3	4	7	7	5	SELL	0	---	0
	Credits	7
	Credit	1	15
	Credit	2	20
	Credit	3	16
	Credit	4	9
	Credit	5	5
	Credit	6	10
	Credit	7	20
	Ownerships	7
	Ownership	1	17
	Ownership	2	7
	Ownership	3	72
	Ownership	4	57
	Ownership	5	41
	Ownership	6	42
	Ownership	7	42
	ReferencePrice	5
	StaticPriceBandLowerLimit	0.6
	StaticPriceBandUpperLimit	0.8
	TotalShares	100
	OwnershipUpperLimit	0.2
	TickSize	1
	LotSize	1
Limit	9	4	4	4	5	SELL	0	---	0
NewOrderRs	Accepted
	Trades	0
	Orders	3
	Order	Iceberg	7	2	6	4	5	SELL	0	---	3
	Order	Limit	9	4	4	4	5	SELL	0	---	0
	Order	Limit	3	4	7	7	5	SELL	0	---	0
	Credits	7
	Credit	1	15
	Credit	2	20
	Credit	3	16
	Credit	4	9
	Credit	5	5
	Credit	6	10
	Credit	7	20
	Ownerships	7
	Ownership	1	17
	Ownership	2	7
	Ownership	3	72
	Ownership	4	57
	Ownership	5	41
	Ownership	6	42
	Ownership	7	42
	ReferencePrice	5
	StaticPriceBandLowerLimit	0.6
	StaticPriceBandUpperLimit	0.8
	TotalShares	100
	OwnershipUpperLimit	0.2
	TickSize	1
	LotSize	1
Limit	10	4	4	7	3	SELL	0	FAK	0
ReplaceOrderRs	Eliminated
	Trades	0
	Orders	2
	Order	Iceberg	7	2	6	4	5	SELL	0	---	3
	Order	Limit	3	4	7	7	5	SELL	0	---	0
	Credits	7
	Credit	1	15
	Credit	2	20
	Credit	3	16
	Credit	4	9
	Credit	5	5
	Credit	6	10
	Credit	7	20
	Ownerships	7
	Ownership	1	17
	Ownership	2	7
	Ownership	3	72
	Ownership	4	57
	Ownership	5	41
	Ownership	6	42
	Ownership	7	42
	ReferencePrice	5
	StaticPriceBandLowerLimit	0.6
	StaticPriceBandUpperLimit	0.8
	TotalShares	100
	OwnershipUpperLimit	0.2
	TickSize	1
	LotSize	1
Iceberg	11	4	6	4	2	SELL	2	---	0
NewOrderRs	Eliminated
	Trades	0
	Orders	2
	Order	Iceberg	7	2	6	4	5	SELL	0	---	3
	Order	Limit	3	4	7	7	5	SELL	0	---	0
	Credits	7
	Credit	1	15
	Credit	2	20
	Credit	3	16
	Credit	4	9
	Credit	5	5
	Credit	6	10
	Credit	7	20
	Ownerships	7
	Ownership	1	17
	Ownership	2	7
	Ownership	3	72
	Ownership	4	57
	Ownership	5	41
	Ownership	6	42
	Ownership	7	42
	ReferencePrice	5
	StaticPriceBandLowerLimit	0.6
	StaticPriceBandUpperLimit	0.8
	TotalShares	100
	OwnershipUpperLimit	0.2
	TickSize	1
	LotSize	1
Iceberg	12	5	2	7	3	BUY 	2	---	0
NewOrderRs	Rejected
	Trades	0
	Orders	2
	Order	Iceberg	7	2	6	4	5	SELL	0	---	3
	Order	Limit	3	4	7	7	5	SELL	0	---	0
	Credits	7
	Credit	1	15
	Credit	2	20
	Credit	3	16
	Credit	4	9
	Credit	5	5
	Credit	6	10
	Credit	7	20
	Ownerships	7
	Ownership	1	17
	Ownership	2	7
	Ownership	3	72
	Ownership	4	57
	Ownership	5	41
	Ownership	6	42
	Ownership	7	42
	ReferencePrice	5
	StaticPriceBandLowerLimit	0.6
	StaticPriceBandUpperLimit	0.8
	TotalShares	100
	OwnershipUpperLimit	0.2
	TickSize	1
	LotSize	1
Limit	13	4	6	8	1	SELL	0	---	0
NewOrderRs	Accepted
	Trades	0
	Orders	3
	Order	Iceberg	7	2	6	4	5	SELL	0	---	3
	Order	Limit	3	4	7	7	5	SELL	0	---	0
	Order	Limit	13	4	6	8	1	SELL	0	---	0
	Credits	7
	Credit	1	15
	Credit	2	20
	Credit	3	16
	Credit	4	9
	Credit	5	5
	Credit	6	10
	Credit	7	20
	Ownerships	7
	Ownership	1	17
	Ownership	2	7
	Ownership	3	72
	Ownership	4	57
	Ownership	5	41
	Ownership	6	42
	Ownership	7	42
	ReferencePrice	5
	StaticPriceBandLowerLimit	0.6
	StaticPriceBandUpperLimit	0.8
	TotalShares	100
	OwnershipUpperLimit	0.2
	TickSize	1
	LotSize	1
Limit	14	7	2	1	2	BUY 	0	---	0
NewOrderRs	Rejected
	Trades	0
	Orders	3
	Order	Iceberg	7	2	6	4	5	SELL	0	---	3
	Order	Limit	3	4	7	7	5	SELL	0	---	0
	Order	Limit	13	4	6	8	1	SELL	0	---	0
	Credits	7
	Credit	1	15
	Credit	2	20
	Credit	3	16
	Credit	4	9
	Credit	5	5
	Credit	6	10
	Credit	7	20
	Ownerships	7
	Ownership	1	17
	Ownership	2	7
	Ownership	3	72
	Ownership	4	57
	Ownership	5	41
	Ownership	6	42
	Ownership	7	42
	ReferencePrice	5
	StaticPriceBandLowerLimit	0.6
	StaticPriceBandUpperLimit	0.8
	TotalShares	100
	OwnershipUpperLimit	0.2
	TickSize	1
	LotSize	1
CancelOrderRs	Rejected
	Orders	3
	Order	Iceberg	7	2	6	4	5	SELL	0	---	3
	Order	Limit	3	4	7	7	5	SELL	0	---	0
	Order	Limit	13	4	6	8	1	SELL	0	---	0
	Credits	7
	Credit	1	15
	Credit	2	20
	Credit	3	16
	Credit	4	9
	Credit	5	5
	Credit	6	10
	Credit	7	20
	Ownerships	7
	Ownership	1	17
	Ownership	2	7
	Ownership	3	72
	Ownership	4	57
	Ownership	5	41
	Ownership	6	42
	Ownership	7	42
	ReferencePrice	5
	StaticPriceBandLowerLimit	0.6
	StaticPriceBandUpperLimit	0.8
	TotalShares	100
	OwnershipUpperLimit	0.2
	TickSize	1
	LotSize	1
Limit	16	5	3	4	1	BUY 	0	FAK	0
NewOrderRs	Rejected
	Trades	0
	Orders	3
	Order	Iceberg	7	2	6	4	5	SELL	0	---	3
	Order	Limit	3	4	7	7	5	SELL	0	---	0
	Order	Limit	13	4	6	8	1	SELL	0	---	0
	Credits	7
	Credit	1	15
	Credit	2	20
	Credit	3	16
	Credit	4	9
	Credit	5	5
	Credit	6	10
	Credit	7	20
	Ownerships	7
	Ownership	1	17
	Ownership	2	7
	Ownership	3	72
	Ownership	4	57
	Ownership	5	41
	Ownership	6	42
	Ownership	7	42
	ReferencePrice	5
	StaticPriceBandLowerLimit	0.6
	StaticPriceBandUpperLimit	0.8
	TotalShares	100
