reported_result/report-0/ART/output/output2.txt

Iceberg	1	7	4	3	5	SELL	0	---	0
NewOrderRs	Accepted
	Trades	0
	Orders	1
	Order	Iceberg	1	7	4	3	5	SELL	0	---	4
	Credits	7
	Credit	1	7
	Credit	2	12
	Credit	3	14
	Credit	4	6
	Credit	5	14
	Credit	6	10
	Credit	7	4
	Ownerships	7
	Ownership	1	56
	Ownership	2	90
	Ownership	3	23
	Ownership	4	74
	Ownership	5	92
	Ownership	6	38
	Ownership	7	49
	ReferencePrice	5
	StaticPriceBandLowerLimit	0.6
	StaticPriceBandUpperLimit	0.8
	TotalShares	100
	OwnershipUpperLimit	0.2
	TickSize	1
	LotSize	1
Limit	2	6	1	9	4	BUY 	0	---	0
NewOrderRs	Rejected
	Trades	0
	Orders	1
	Order	Iceberg	1	7	4	3	5	SELL	0	---	4
	Credits	7
	Credit	1	7
	Credit	2	12
	Credit	3	14
	Credit	4	6
	Credit	5	14
	Credit	6	10
	Credit	7	4
	Ownerships	7
	Ownership	1	56
	Ownership	2	90
	Ownership	3	23
	Ownership	4	74
	Ownership	5	92
	Ownership	6	38
	Ownership	7	49
	ReferencePrice	5
	StaticPriceBandLowerLimit	0.6
	StaticPriceBandUpperLimit	0.8
	TotalShares	100
	OwnershipUpperLimit	0.2
	TickSize	1
	LotSize	1
Iceberg	3	7	1	4	5	SELL	4	---	0
NewOrderRs	Eliminated
	Trades	0
	Orders	1
	Order	Iceberg	1	7	4	3	5	SELL	0	---	4
	Credits	7
	Credit	1	7
	Credit	2	12
	Credit	3	14
	Credit	4	6
	Credit	5	14
	Credit	6	10
	Credit	7	4
	Ownerships	7
	Ownership	1	56
	Ownership	2	90
	Ownership	3	23
	Ownership	4	74
	Ownership	5	92
	Ownership	6	38
	Ownership	7	49
	ReferencePrice	5
	StaticPriceBandLowerLimit	0.6
	StaticPriceBandUpperLimit	0.8
	TotalShares	100
	OwnershipUpperLimit	0.2
	TickSize	1
	LotSize	1
Limit	4	2	4	1	2	BUY 	0	FAK	0
NewOrderRs	Rejected
	Trades	0
	Orders	1
	Order	Iceberg	1	7	4	3	5	SELL	0	---	4
	Credits	7
	Credit	1	7
	Credit	2	12
	Credit	3	14
	Credit	4	6
	Credit	5	14
	Credit	6	10
	Credit	7	4
	Ownerships	7
	Ownership	1	56
	Ownership	2	90
	Ownership	3	23
	Ownership	4	74
	Ownership	5	92
	Ownership	6	38
	Ownership	7	49
	ReferencePrice	5
	StaticPriceBandLowerLimit	0.6
	StaticPriceBandUpperLimit	0.8
	TotalShares	100
	OwnershipUpperLimit	0.2
	TickSize	1
	LotSize	1
CancelOrderRs	Rejected
	Orders	1
	Order	Iceberg	1	7	4	3	5	SELL	0	---	4
	Credits	7
	Credit	1	7
	Credit	2	12
	Credit	3	14
	Credit	4	6
	Credit	5	14
	Credit	6	10
	Credit	7	4
	Ownerships	7
	Ownership	1	56
	Ownership	2	90
	Ownership	3	23
	Ownership	4	74
	Ownership	5	92
	Ownership	6	38
	Ownership	7	49
	ReferencePrice	5
	StaticPriceBandLowerLimit	0.6
	StaticPriceBandUpperLimit	0.8
	TotalShares	100
	OwnershipUpperLimit	0.2
	TickSize	1
	LotSize	1
Limit	6	4	4	7	1	BUY 	0	---	0
NewOrderRs	Rejected
	Trades	0
	Orders	1
	Order	Iceberg	1	7	4	3	5	SELL	0	---	4
	Credits	7
	Credit	1	7
	Credit	2	12
	Credit	3	14
	Credit	4	6
	Credit	5	14
	Credit	6	10
	Credit	7	4
	Ownerships	7
	Ownership	1	56
	Ownership	2	90
	Ownership	3	23
	Ownership	4	74
	Ownership	5	92
	Ownership	6	38
	Ownership	7	49
	ReferencePrice	5
	StaticPriceBandLowerLimit	0.6
	StaticPriceBandUpperLimit	0.8
	TotalShares	100
	OwnershipUpperLimit	0.2
	TickSize	1
	LotSize	1
Limit	7	4	3	7	2	BUY 	0	FAK	0
NewOrderRs	Rejected
	Trades	0
	Orders	1
	Order	Iceberg	1	7	4	3	5	SELL	0	---	4
	Credits	7
	Credit	1	7
	Credit	2	12
	Credit	3	14
	Credit	4	6
	Credit	5	14
	Credit	6	10
	Credit	7	4
	Ownerships	7
	Ownership	1	56
	Ownership	2	90
	Ownership	3	23
	Ownership	4	74
	Ownership	5	92
	Ownership	6	38
	Ownership	7	49
	ReferencePrice	5
	StaticPriceBandLowerLimit	0.6
	StaticPriceBandUpperLimit	0.8
	TotalShares	100
	OwnershipUpperLimit	0.2
	TickSize	1
	LotSize	1
Iceberg	8	7	4	10	3	BUY 	0	---	0
NewOrderRs	Rejected
	Trades	0
	Orders	1
	Order	Iceberg	1	7	4	3	5	SELL	0	---	4
	Credits	7
	Credit	1	7
	Credit	2	12
	Credit	3	14
	Credit	4	6
	Credit	5	14
	Credit	6	10
	Credit	7	4
	Ownerships	7
	Ownership	1	56
	Ownership	2	90
	Ownership	3	23
	Ownership	4	74
	Ownership	5	92
	Ownership	6	38
	Ownership	7	49
	ReferencePrice	5
	StaticPriceBandLowerLimit	0.6
	StaticPriceBandUpperLimit	0.8
	TotalShares	100
	OwnershipUpperLimit	0.2
	TickSize	1
	LotSize	1
Limit	9	7	1	10	1	BUY 	1	---	0
NewOrderRs	Rejected
	Trades	0
	Orders	1
	Order	Iceberg	1	7	4	3	5	SELL	0	---	4
	Credits	7
	Credit	1	7
	Credit	2	12
	Credit	3	14
	Credit	4	6
	Credit	5	14
	Credit	6	10
	Credit	7	4
	Ownerships	7
	Ownership	1	56
	Ownership	2	90
	Ownership	3	23
	Ownership	4	74
	Ownership	5	92
	Ownership	6	38
	Ownership	7	49
	ReferencePrice	5
	StaticPriceBandLowerLimit	0.6
	StaticPriceBandUpperLimit	0.8
	TotalShares	100
	OwnershipUpperLimit	0.2
	TickSize	1
	LotSize	1
Iceberg	10	7	1	2	2	BUY 	1	---	0
ReplaceOrderRs	Rejected
	Trades	0
	Orders	1
	Order	Iceberg	1	7	4	3	5	SELL	0	---	4
	Credits	7
	Credit	1	7
	Credit	2	12
	Credit	3	14
	Credit	4	6
	Credit	5	14
	Credit	6	10
	Credit	7	4
	Ownerships	7
	Ownership	1	56
	Ownership	2	90
	Ownership	3	23
	Ownership	4	74
	Ownership	5	92
	Ownership	6	38
	Ownership	7	49
	ReferencePrice	5
	StaticPriceBandLowerLimit	0.6
	StaticPriceBandUpperLimit	0.8
	TotalShares	100
	OwnershipUpperLimit	0.2
	TickSize	1
	LotSize	1
Iceberg	11	4	3	5	2	BUY 	1	---	0
NewOrderRs	Rejected
	Trades	0
	Orders	1
	Order	Iceberg	1	7	4	3	5	SELL	0	---	4
	Credits	7
	Credit	1	7
	Credit	2	12
	Credit	3	14
	Credit	4	6
	Credit	5	14
	Credit	6	10
	Credit	7	4
	Ownerships	7
	Ownership	1	56
	Ownership	2	90
	Ownership	3	23
	Ownership	4	74
	Ownership	5	92
	Ownership	6	38
	Ownership	7	49
	ReferencePrice	5
	StaticPriceBandLowerLimit	0.6
	StaticPriceBandUpperLimit	0.8
	TotalShares	100
	OwnershipUpperLimit	0.2
	TickSize	1
	LotSize	1
Iceberg	12	5	1	7	4	SELL	0	---	0
NewOrderRs	Accepted
	Trades	0
	Orders	2
	Order	Iceberg	1	7	4	3	5	SELL	0	---	4
	Order	Iceberg	12	5	1	7	4	SELL	0	---	4
	Credits	7
	Credit	1	7
	Credit	2	12
	Credit	3	14
	Credit	4	6
	Credit	5	14
	Credit	6	10
	Credit	7	4
	Ownerships	7
	Ownership	1	56
	Ownership	2	90
	Ownership	3	23
	Ownership	4	74
	Ownership	5	92
	Ownership	6	38
	Ownership	7	49
	ReferencePrice	5
	StaticPriceBandLowerLimit	0.6
	StaticPriceBandUpperLimit	0.8
	TotalShares	100
	OwnershipUpperLimit	0.2
	TickSize	1
	LotSize	1
Limit	13	2	3	3	1	SELL	0	FAK	0
NewOrderRs	Eliminated
	Trades	0
	Orders	2
	Order	Iceberg	1	7	4	3	5	SELL	0	---	4
	Order	Iceberg	12	5	1	7	4	SELL	0	---	4
	Credits	7
	Credit	1	7
	Credit	2	12
	Credit	3	14
	Credit	4	6
	Credit	5	14
	Credit	6	10
	Credit	7	4
	Ownerships	7
	Ownership	1	56
	Ownership	2	90
	Ownership	3	23
	Ownership	4	74
	Ownership	5	92
	Ownership	6	38
	Ownership	7	49
	ReferencePrice	5
	StaticPriceBandLowerLimit	0.6
	StaticPriceBandUpperLimit	0.8
	TotalShares	100
	OwnershipUpperLimit	0.2
	TickSize	1
	LotSize	1
Limit	14	7	3	3	5	BUY 	2	---	0
NewOrderRs	Rejected
	Trades	0
	Orders	2
	Order	Iceberg	1	7	4	3	5	SELL	0	---	4
	Order	Iceberg	12	5	1	7	4	SELL	0	---	4
	Credits	7
	Credit	1	7
	Credit	2	12
	Credit	3	14
	Credit	4	6
	Credit	5	14
	Credit	6	10
	Credit	7	4
	Ownerships	7
	Ownership	1	56
	Ownership	2	90
	Ownership	3	23
	Ownership	4	74
	Ownership	5	92
	Ownership	6	38
	Ownership	7	49
	ReferencePrice	5
	StaticPriceBandLowerLimit	0.6
	StaticPriceBandUpperLimit	0.8
	TotalShares	100
	OwnershipUpperLimit	0.2
	TickSize	1
	LotSize	1
CancelOrderRs	Rejected
	Orders	2
	Order	Iceberg	1	7	4	3	5	SELL	0	---	4
	Order	Iceberg	12	5	1	7	4	SELL	0	---	4
	Credits	7
	Credit	1	7
	Credit	2	12
	Credit	3	14
	Credit	4	6
	Credit	5	14
	Credit	6	10
	Credit	7	4
	Ownerships	7
	Ownership	1	56
	Ownership	2	90
	Ownership	3	23
	Ownership	4	74
	Ownership	5	92
	Ownership	6	38
	Ownership	7	49
	ReferencePrice	5
	StaticPriceBandLowerLimit	0.6
	StaticPriceBandUpperLimit	0.8
	TotalShares	100
	OwnershipUpperLimit	0.2
	TickSize	1
	LotSize	1
Iceberg	16	7	7	7	1	SELL	1	---	0
NewOrderRs	Eliminated
	Trades	0
	Orders	2
	Order	Iceberg	1	7	4	3	5	SELL	0	---	4
	Order	Iceberg	12	5	1	7	4	SELL	0	---	4
	Credits	7
	Credit	1	7
	Credit	2	12
	Credit	3	14
	Credit	4	6
	Credit	5	14
	Credit	6	10
	Credit	7	4
	Ownerships	7
	Ownership	1	56
	Ownership	2	90
	Ownership	3	23
	Ownership	4	74
	Ownership	5	92
	Ownership	6	38
	Ownership	7	49
	ReferencePrice	5
	StaticPriceBandLowerLimit	0.6
	StaticPriceBandUpperLimit	0.8
	TotalShares	100
	OwnershipUpperLimit	0.2
	TickSize	1
	LotSize	1
Limit	17	2	7	1	3	SELL	1	---	0
NewOrderRs	Rejected
	Trades	0
	Orders	2
	Order	Iceberg	1	7	4	3	5	SELL	0	---	4
	Order	Iceberg	12	5	1	7	4	SELL	0	---	4
	Credits	7
	Credit	1	7
	Credit	2	12
	Credit	3	14
	Credit	4	6
	Credit	5	14
